<?xml version="1.0" encoding="utf-8"?>
<!-- =================================================================================== -->
<!-- |    This document was autogenerated by xacro from brokk.urdf.xacro               | -->
<!-- |    EDITING THIS FILE BY HAND IS NOT RECOMMENDED                                 | -->
<!-- =================================================================================== -->
<robot name="brokk">
  <gazebo>
    <plugin filename="libgazebo_ros_control.so" name="gazebo_ros_control">
      <robotNamespace/>
      <robotSimType>gazebo_ros_control/DefaultRobotHWSim</robotSimType>
    </plugin>
    <!--
    <plugin name="gazebo_ros_power_monitor_controller" filename="libgazebo_ros_power_monitor.so">
      <alwaysOn>true</alwaysOn>
      <updateRate>1.0</updateRate>
      <timeout>5</timeout>
      <powerStateTopic>power_state</powerStateTopic>
      <powerStateRate>10.0</powerStateRate>
      <fullChargeCapacity>87.78</fullChargeCapacity>     
      <dischargeRate>-474</dischargeRate>
      <chargeRate>525</chargeRate>
      <dischargeVoltage>15.52</dischargeVoltage>
      <chargeVoltage>16.41</chargeVoltage>
    </plugin>
-->
  </gazebo>
  <!-- Link 3 -->
  <!-- arm -->
  <link name="world">
    <visual>
      <geometry>
        <mesh filename="package://brokk_arm_description/meshes/legs.STL" scale="0.01 0.01 0.01"/>
      </geometry>
      <material name="LightGrey">
        <color rgba="0.7 0.7 0.7 1.0"/>
      </material>
    </visual>
    <collision>
      <origin rpy="0 0 0" xyz="0 0 0"/>
      <geometry>
        <mesh filename="package://brokk_arm_description/meshes/legs.STL" scale="0.01 0.01 0.01"/>
      </geometry>
    </collision>
    <inertial>
      <mass value="1.0"/>
      <inertia ixx="1.0" ixy="0.0" ixz="0.0" iyy="1.0" iyz="0.0" izz="1.0"/>
    </inertial>
  </link>
  <link name="brokk_base">
    <visual>
      <geometry>
        <mesh filename="package://brokk_arm_description/meshes/base.STL" scale="0.01 0.01 0.01"/>
      </geometry>
      <material name="LightGrey">
        <color rgba="0.7 0.7 0.7 1.0"/>
      </material>
    </visual>
    <collision>
      <origin rpy="0 0 0" xyz="0 0 0"/>
      <geometry>
        <mesh filename="package://brokk_arm_description/meshes/base.STL" scale="0.01 0.01 0.01"/>
      </geometry>
    </collision>
    <inertial>
      <mass value="1.0"/>
      <inertia ixx="1.0" ixy="0.0" ixz="0.0" iyy="1.0" iyz="0.0" izz="1.0"/>
    </inertial>
  </link>
  <joint name="brokk_jnt0" type="revolute">
    <parent link="world"/>
    <child link="brokk_base"/>
    <origin rpy="0.0 0.0 0.62" xyz="0 0.0 0.65"/>
    <axis xyz="0 0 0"/>
    <limit effort="330.0" lower="-3.14159265359" upper="3.14159265359" velocity="3.14"/>
    <dynamics damping="100"/>
  </joint>
  <link name="brokk_body1">
    <visual>
      <geometry>
        <mesh filename="package://brokk_arm_description/meshes/body1.STL" scale="0.01 0.01 0.01"/>
      </geometry>
      <material name="LightGrey">
        <color rgba="0.7 0.7 0.7 1.0"/>
      </material>
    </visual>
    <collision>
      <origin rpy="0 0 0" xyz="0 0 0"/>
      <geometry>
        <mesh filename="package://brokk_arm_description/meshes/body1.STL" scale="0.01 0.01 0.01"/>
      </geometry>
    </collision>
    <inertial>
      <mass value="1.0"/>
      <inertia ixx="1.0" ixy="0.0" ixz="0.0" iyy="1.0" iyz="0.0" izz="1.0"/>
    </inertial>
  </link>
  <joint name="brokk_jnt1" type="revolute">
    <parent link="brokk_base"/>
    <child link="brokk_body1"/>
    <origin rpy="0.0 0 0.0" xyz="0.33 0 0.14"/>
    <axis xyz="0 1 0"/>
    <limit effort="330.0" lower="-3.14159265359" upper="3.14159265359" velocity="3.14"/>
    <dynamics damping="100"/>
  </joint>
  <link name="brokk_body2">
    <visual>
      <geometry>
        <mesh filename="package://brokk_arm_description/meshes/body2.STL" scale="0.01 0.01 0.01"/>
      </geometry>
      <material name="LightGrey">
        <color rgba="0.7 0.7 0.7 1.0"/>
      </material>
    </visual>
    <collision>
      <origin rpy="0 0 0" xyz="0 0 0"/>
      <geometry>
        <mesh filename="package://brokk_arm_description/meshes/body2.STL" scale="0.01 0.01 0.01"/>
      </geometry>
    </collision>
    <inertial>
      <mass value="1.0"/>
      <inertia ixx="1.0" ixy="0.0" ixz="0.0" iyy="1.0" iyz="0.0" izz="1.0"/>
    </inertial>
  </link>
  <joint name="brokk_jnt2" type="revolute">
    <parent link="brokk_body1"/>
    <child link="brokk_body2"/>
    <origin rpy="0.0 0.0 0.0" xyz="0 0 0.85"/>
    <axis xyz="0 1 0"/>
    <limit effort="150.0" lower="-3.14159265359" upper="3.14159265359" velocity="3.14"/>
    <dynamics damping="100"/>
  </joint>
  <link name="brokk_body3">
    <visual>
      <geometry>
        <mesh filename="package://brokk_arm_description/meshes/body3.STL" scale="0.01 0.01 0.01"/>
      </geometry>
      <material name="LightGrey">
        <color rgba="0.7 0.7 0.7 1.0"/>
      </material>
    </visual>
    <collision>
      <origin rpy="0 0 0" xyz="0 0 0"/>
      <geometry>
        <mesh filename="package://brokk_arm_description/meshes/body3.STL" scale="0.01 0.01 0.01"/>
      </geometry>
    </collision>
    <inertial>
      <mass value="1.0"/>
      <inertia ixx="1.0" ixy="0.0" ixz="0.0" iyy="1.0" iyz="0.0" izz="1.0"/>
    </inertial>
  </link>
  <joint name="brokk_jnt3" type="revolute">
    <parent link="brokk_body2"/>
    <child link="brokk_body3"/>
    <origin rpy="0.0 0 0.0" xyz="1.36 0.0 0"/>
    <axis xyz="0 1 0"/>
    <limit effort="54.0" lower="-3.14159265359" upper="3.14159265359" velocity="6.28"/>
    <dynamics damping="100"/>
  </joint>
  <link name="brokk_body4">
    <visual>
      <geometry>
        <mesh filename="package://brokk_arm_description/meshes/body4.STL" scale="0.01 0.01 0.01"/>
      </geometry>
      <material name="LightGrey">
        <color rgba="0.7 0.7 0.7 1.0"/>
      </material>
    </visual>
    <collision>
      <origin rpy="0 0 0" xyz=" 0 0 0"/>
      <geometry>
        <mesh filename="package://brokk_arm_description/meshes/body4.STL" scale="0.01 0.01 0.01"/>
      </geometry>
    </collision>
    <inertial>
      <mass value="1.0"/>
      <inertia ixx="1.0" ixy="0.0" ixz="0.0" iyy="1.0" iyz="0.0" izz="1.0"/>
    </inertial>
  </link>
  <joint name="brokk_jnt4" type="revolute">
    <parent link="brokk_body3"/>
    <child link="brokk_body4"/>
    <origin rpy="0.0 0.0 0.0" xyz="0.88 0 0.0"/>
    <axis xyz="0 1 0"/>
    <limit effort="54.0" lower="-3.14159265359" upper="3.14159265359" velocity="6.28"/>
    <dynamics damping="100"/>
  </joint>
  <link name="brokk_tip">
    <visual>
      <geometry>
        <mesh filename="package://brokk_arm_description/meshes/tip.STL" scale="0.01 0.01 0.01"/>
      </geometry>
      <material name="LightGrey">
        <color rgba="0.7 0.7 0.7 1.0"/>
      </material>
    </visual>
    <collision>
      <origin rpy="0 0 0" xyz="0 0 0"/>
      <geometry>
        <mesh filename="package://brokk_arm_description/meshes/tip.STL" scale="0.01 0.01 0.01"/>
      </geometry>
    </collision>
    <inertial>
      <mass value="1.0"/>
      <inertia ixx="1.0" ixy="0.0" ixz="0.0" iyy="1.0" iyz="0.0" izz="1.0"/>
    </inertial>
  </link>
  <joint name="brokk_jnt5" type="fixed">
    <parent link="brokk_body4"/>
    <child link="brokk_tip"/>
    <origin rpy="0.0 0.0 0.0" xyz="1.25 0 0.08"/>
    <axis xyz="0 1 0"/>
    <limit effort="54.0" lower="-3.14159265359" upper="3.14159265359" velocity="6.28"/>
    <dynamics damping="100"/>
  </joint>
  
</robot>
