<?xml version="1.0" ?>
<robot name="testurdf" xmlns:xacro="http://ros.org/wiki/xacro">
  <xacro:include filename="$(find brokk)/description/common_properties.xacro"/>
  <xacro:include filename="$(find brokk)/description/brokk170_gazebo.xacro"/>
  <xacro:include filename="$(find brokk)/description/brokk170_control.xacro"/>

  <xacro:arg name="use_ros2_control" default="true"/>

  <xacro:property name="joint_damping" value="100"/>
  <xacro:property name="PI" value="3.1415926535897931"/>
  <xacro:property name="mass" value="1" /> <!-- arbitrary value for mass -->
  <xacro:property name="width" value="0.1" /> <!-- Square dimensions (widthxwidth) of beams -->
  <xacro:property name="height1" value="2" /> <!-- Link 1 -->
  <xacro:property name="height2" value="1" /> <!-- Link 2 -->
  <xacro:property name="height3" value="1" /> <!-- Link 3 -->

  <xacro:property name="r200_cam_rgb_px" value="0.005"/>
  <xacro:property name="r200_cam_rgb_py" value="0.018"/>
  <xacro:property name="r200_cam_rgb_pz" value="0.013"/>
  <xacro:property name="r200_cam_depth_offset" value="0.01"/>

  <xacro:property name="brokk_base_lower_limit" value="0.152"/>
  <xacro:property name="brokk_base_upper_limit" value="2.983"/>
  <xacro:property name="brokk_body1_lower_limit" value="0.2513"/>
  <xacro:property name="brokk_body1_upper_limit" value="2.2617"/>
  <xacro:property name="brokk_body2_lower_limit" value="0.076"/>
  <xacro:property name="brokk_body2_upper_limit" value="1.444"/>
  <xacro:property name="brokk_body3_lower_limit" value="0.096"/>
  <xacro:property name="brokk_body3_upper_limit" value="1.824"/>
  <xacro:property name="brokk_body4_lower_limit" value="0.128"/>
  <xacro:property name="brokk_body4_upper_limit" value="2.4367"/>
  <xacro:property name="safety_limits" value="0.15"/>
  <xacro:property name="brokk_arm_vel_limit" value="50.0"/>
  <xacro:property name="k_velocity" value="1.0"/>

  <!--
  <xacro:macro name="brokk_arm" params="prefix joint_limited
    brokk_base_lower_limit:=0.152     brokk_base_upper_limit:=2.983
    brokk_body1_lower_limit:=0.2513    brokk_body1_upper_limit:=2.2617
    brokk_body2_lower_limit:=0.076    brokk_body2_upper_limit:=1.444
    brokk_body3_lower_limit:=0.096    brokk_body3_upper_limit:=1.824
    brokk_body4_lower_limit:=0.128    brokk_body4_upper_limit:=2.4367
    safety_limits:=true safety_pos_margin:=0.15
    brokk_arm_vel_limit:=50.0
    k_velocity :=1.0
    description_pkg:='brokk_arm_description'">
  </xacro:macro>
  -->

  <link name="base_footprint">
  </link>
  

  <joint name="base_joint" type="fixed">
    <parent link="base_footprint"/>
    <child link="base_link"/>
    <origin xyz="0 0 0" rpy="0 0 0"/>
  </joint>

  <link name="base_link">      
  </link> 

  <!-- EINHEIT: BASE LINK / LEGS AND TRACKS __________________________________________________________________________________________________________-->

  <!--$(find brokk)/description/brokk_base_edit.stl   UND   $(find brokk)/description/brokk_base_collision.stl-->
  <!-- Für richtige Darstellungin RVIZ muss man Package:// verwenden, sonst gehen auch die eigentlich effinzienteren ausdrücke oben-->

  <!-- package://brokk/description/brokk_base_edit.stl UND package://brokk/description/brokk_base_collision.stl-->

  <joint name="base_core_joint" type="fixed">
    <parent link="base_footprint"/>
    <child link="base_core_link"/>
    <origin xyz="0 0 0.01" rpy="0 0 0"/>
  </joint>

  <link name="base_core_link">       <!--robot base??-->
    <visual>
          <origin xyz="0.0 0 0.0" rpy="0 0 0" />
          <geometry>
              <mesh filename="package://brokk/models/meshes/brokk_base_edit.stl " scale="0.011 0.01 0.01"/>
          </geometry>
          <material name="LightGrey">
              <color rgba="0.7 0.7 0.7 1.0"/>
          </material>
      </visual>

      <collision>
          <origin xyz="-0.0 0 0.047" rpy="0 0 0"/>
          <geometry>
     	       <mesh filename="package://brokk/models/meshes/brokk_base_collision.stl"/> <!--1.725 0.52 0.6-->
          </geometry>
      </collision>

      <inertial>
        <origin xyz="0 0 0" rpy="0 0 0" />
        <mass value="2.34"/>
        <inertia ixx="1.0" ixy="0.0" ixz="0.0" iyy="1.0" iyz="0.0" izz="1.0" />
      </inertial>

  </link> 

  <!--EINHEIT: IMU_LINK ____________________________________________________________________________________________________________________________-->

  <link name="imu_link"/>

  <joint name="imu_joint" type="fixed">
    <parent link="base_footprint"/>
    <child link="imu_link"/>
    <origin xyz="0.0 0 0.047" rpy="0 0 0"/>
  </joint>

<!-- Einheit-->

  <joint name="wheel_left_behind_joint" type="continuous">
    <parent link="base_link"/>
    <child link="wheel_left_behind_link"/>
    <origin xyz="-0.46 0.40 0.18" rpy="0 0 0"/>
    <axis xyz="0 1 0"/>
  </joint>

  <link name="wheel_left_behind_link">
    <visual>
      <origin xyz="0.0 0.0 0.0" rpy="1.57 0 0"/>
      <geometry>
     	 <cylinder radius="0.18" length="0.20"/>
      </geometry>
      <material name="green"/>
    </visual>

    <collision>
      <origin xyz="0 0 0.0" rpy="1.57 0 0"/>
      <geometry>
        <cylinder length="0.2" radius="0.18"/>
      </geometry>
    </collision>

    <inertial>
      <origin xyz="0 0 0.0" />
      <mass value="2.8498940e-02" />
      <inertia ixx="1.1175580e-05" ixy="-4.2369783e-11" ixz="-5.9381719e-09"
               iyy="1.1192413e-05" iyz="-1.4400107e-11"
               izz="2.0712558e-05" />
      </inertial>
  </link>
  
	<!-- linker mittel hinten Reifen loo0o-->	
	
  <joint name="wheel_left_mittelhinten_joint" type="continuous">
    <parent link="base_footprint"/>
    <child link="wheel_left_mittelhinten_link"/>
    <origin xyz="-0.09 0.40 0.18" rpy="0 0 0"/>
    <axis xyz="0 1 0"/>
  </joint>
  
  <link name="wheel_left_mittelhinten_link">
    <visual>
      <origin xyz="0.0 0.0 0.0" rpy="1.57 0 0"/>
      <geometry>
     	 <cylinder radius="0.18" length="0.20"/>
      </geometry>
      <material name="dark"/>
    </visual>

    <collision>
      <origin xyz="0.0 0 0.0" rpy="1.57 0 0"/>
      <geometry>
        <cylinder length="0.2" radius="0.18"/>
      </geometry>
    </collision>

    <inertial>
      <origin xyz="0.0 0 0.0" />
      <mass value="2.8498940e-02" />
      <inertia ixx="1.1175580e-05" ixy="-4.2369783e-11" ixz="-5.9381719e-09"
               iyy="1.1192413e-05" iyz="-1.4400107e-11"
               izz="2.0712558e-05" />
      </inertial>
  </link>
	
	<!-- linker mittel vorne Reifen lo0oo-->
	
  <joint name="wheel_left_mittelvorne_joint" type="continuous">
    <parent link="base_footprint"/>
    <child link="wheel_left_mittelvorne_link"/>
    <origin xyz="0.28 0.4 0.18" rpy="0 0 0"/>
    <axis xyz="0 1 0"/>
  </joint>
  
  <link name="wheel_left_mittelvorne_link">
    <visual>
      <origin xyz="0 0 0" rpy="1.57 0 0"/>
      <geometry>
     	 <cylinder radius="0.18" length="0.2"/>
      </geometry>
      <material name="dark"/>
    </visual>

    <collision>
      <origin xyz="0 0 0" rpy="1.57 0 0"/>
      <geometry>
        <cylinder length="0.2" radius="0.18"/>
      </geometry>
    </collision>

    <inertial>
      <origin xyz="0 0 0" />
      <mass value="2.8498940e-02" />
      <inertia ixx="1.1175580e-05" ixy="-4.2369783e-11" ixz="-5.9381719e-09"
               iyy="1.1192413e-05" iyz="-1.4400107e-11"
               izz="2.0712558e-05" />
      </inertial>
  </link>
	
	<!-- rechter mittel hinten Reifen roo0o-->
	
  <joint name="wheel_right_mittelhinten_joint" type="continuous">
    <parent link="base_footprint"/>
    <child link="wheel_right_mittelhinten_link"/>
    <origin xyz="-0.08 -0.4 0.18" rpy="0 0 0"/>
    <axis xyz="0 1 0"/>
  </joint>
  
  <link name="wheel_right_mittelhinten_link">
    <visual>
      <origin xyz="0.0 0 0.0" rpy="-1.57 0 0"/>
      <geometry>
      	<cylinder radius="0.18" length="0.2"/>
      </geometry>
      <material name="dark"/>
    </visual>

    <collision>
      <origin xyz="0.0 0 0.0" rpy="-1.57 0 0"/>
      <geometry>
      	<cylinder radius="0.18" length="0.2"/>
      </geometry>
    </collision>

    <inertial>
      <origin xyz="0.0 0 0.0" />
      <mass value="2.8498940e-02" />
      <inertia ixx="1.1175580e-05" ixy="-4.2369783e-11" ixz="-5.9381719e-09"
               iyy="1.1192413e-05" iyz="-1.4400107e-11"
               izz="2.0712558e-05" />
      </inertial>
  </link>
	
	
	<!-- rechter mittel vorne Reifen ro0oo-->
	
  <joint name="wheel_right_mittelvorne_joint" type="continuous">
    <parent link="base_footprint"/>
    <child link="wheel_right_mittelvorne_link"/>
    <origin xyz="0.28 -0.4 0.18" rpy="0 0 0"/>
    <axis xyz="0 1 0"/>
  </joint>
  
  <link name="wheel_right_mittelvorne_link">
    <visual>
      <origin xyz="0 0 0.0" rpy="-1.57 0 0"/>
      <geometry>
      	<cylinder radius="0.18" length="0.2"/>
      </geometry>
      <material name="dark"/>
    </visual>

    <collision>
      <origin xyz="0 0 0" rpy="-1.57 0 0"/>
      <geometry>
      	<cylinder radius="0.18" length="0.2"/>
      </geometry>
    </collision>

    <inertial>
      <origin xyz="0 0 0.0" />
      <mass value="2.8498940e-02" />
      <inertia ixx="1.1175580e-05" ixy="-4.2369783e-11" ixz="-5.9381719e-09"
               iyy="1.1192413e-05" iyz="-1.4400107e-11"
               izz="2.0712558e-05" />
      </inertial>
  </link>
  
   <!-- linker vorderer Reifen looo0-->

  <joint name="left_joint" type="continuous">
    <origin xyz="0.65 0.4 0.18" rpy="0 0 0"/>
    <parent link="base_footprint"/>
    <child link="wheel_left_link"/>
    <axis xyz="0.0 1.0 0.0"/>
    <dynamics damping="10"/>
  </joint>

  <link name="wheel_left_link">
    <visual>
      <origin xyz="0 0.0 0.0" rpy="1.57 0 0"/>
      <geometry>
      	<cylinder radius="0.18" length="0.2"/>
      </geometry>
      <material name="dark"/>
    </visual>

    <collision>
      <origin xyz="0.0 0 0.0" rpy="1.57 0 0"/>
      <geometry>
        <cylinder length="0.2" radius="0.18"/>
      </geometry>
    </collision>

    <inertial>
      <origin xyz="0 0 0.0" />
      <mass value="2.8498940e-02" />
      <inertia ixx="1.1175580e-05" ixy="-4.2369783e-11" ixz="-5.9381719e-09"
               iyy="1.1192413e-05" iyz="-1.4400107e-11"
               izz="2.0712558e-05" />
      </inertial>
  </link>

 <!-- rechter hinterer Reifen r0ooo -->

  <joint name="wheel_right_behind_joint" type="continuous">
    <parent link="base_footprint"/>
    <child link="wheel_right_behind_link"/>
    <origin xyz="-0.46 -0.4 0.18" rpy="0 0 0"/>
    <axis xyz="0 1 0"/>
    <dynamics damping="20"/>
  </joint>

  <link name="wheel_right_behind_link">
    <visual>
      <origin xyz="0 0 0" rpy="-1.57 0 0"/>
      <geometry>
      	<cylinder radius="0.18" length="0.2"/>
      </geometry>
      <material name="blue"/>
    </visual>

    <collision>
      <origin xyz="0 0 0.0" rpy="-1.57 0 0"/>
      <geometry>
      	<cylinder radius="0.18" length="0.2"/>
      </geometry>
    </collision>

    <inertial>
      <origin xyz="0 0 0.0" />
      <mass value="2.8498940e-02" />
      <inertia ixx="1.1175580e-05" ixy="-4.2369783e-11" ixz="-5.9381719e-09"
               iyy="1.1192413e-05" iyz="-1.4400107e-11"
               izz="2.0712558e-05" />
      </inertial>
  </link>
  
   <!-- rechter vorderer Reifen rooo0-->

  <joint name="right_joint" type="continuous">
    <origin xyz="0.65 -0.4 0.18" rpy="0 0 0"/>
    <parent link="base_footprint"/>
    <child link="wheel_right_link"/>
    <axis xyz="0.0 1.0 0.0"/>
  </joint>

  <!--
  <joint name="wheel_right_rot" type="continuous">
    <origin xyz="0.020002 -0.17 0.124999" rpy="0 0 0"/>
    <parent link="base_link"/>
    <child link="wheel_right_link"/>
    <axis xyz="0.0 1.0 0.0"/>
  </joint>
  -->

  <link name="wheel_right_link">
    <visual>
      <origin xyz="0 0 0.0" rpy="-1.57 0 0"/>
      <geometry>
      	<cylinder radius="0.18" length="0.2"/>
      </geometry>
      <material name="dark"/>
    </visual>

    <collision>
      <origin xyz="0 0 0.0" rpy="-1.57 0 0"/>
      <geometry>
      	<cylinder radius="0.18" length="0.2"/>
      </geometry>
    </collision>

    <inertial>
      <origin xyz="0 0 0.0" />
      <mass value="2.8498940e-02" />
      <inertia ixx="1.1175580e-05" ixy="-4.2369783e-11" ixz="-5.9381719e-09"
               iyy="1.1192413e-05" iyz="-1.4400107e-11"
               izz="2.0712558e-05" />
      </inertial>
  </link>

<!--
<joint name="wheel_left_rot" type="continuous">
  <origin xyz="0.020002 0.17 0.124999" rpy="0 0 0"/>
  <parent link="base_link"/>
  <child link="wheel_left_link"/>
  <axis xyz="0.0 1.0 0.0"/>
</joint>
-->

</robot>


